output file:
processed_visionflow_to_image273.json
function:
flow_to_image
Error Cases:

Pass or Failed: 0

Related Failed Test Cases:
{'../publishablew/vision/vision/test/test_utils.py::test_flow_to_image[False] FAILED', 'FAILED ../publishablew/vision/vision/test/test_utils.py::test_flow_to_image[True]', '../publishablew/vision/vision/test/test_utils.py::test_flow_to_image[True] FAILED', 'FAILED ../publishablew/vision/vision/test/test_utils.py::test_flow_to_image[False]'}

All Test Cases On Generated code:
============================= test session starts ==============================
platform linux -- Python 3.11.10, pytest-8.3.4, pluggy-1.5.0 -- /local/data0/moved_data/publishablew/vision/vision/venv/bin/python
cachedir: .pytest_cache
rootdir: /local/data0/moved_data/publishablew/vision/vision
configfile: pytest.ini
plugins: mock-3.14.0
collecting ... collected 2 items

../publishablew/vision/vision/test/test_utils.py::test_flow_to_image[True] FAILED
../publishablew/vision/vision/test/test_utils.py::test_flow_to_image[False] FAILED

=================================== FAILURES ===================================
___________________________ test_flow_to_image[True] ___________________________
../publishablew/vision/vision/test/test_utils.py:530: in test_flow_to_image
    img = utils.flow_to_image(flow)
../publishablew/vision/vision/venv/lib/python3.11/site-packages/torch/utils/_contextlib.py:116: in decorate_context
    return func(*args, **kwargs)
../publishablew/vision/vision/torchvision/utils.py:339: in flow_to_image
    return flow_to_image(flow)
../publishablew/vision/vision/torchvision/temp.py:33: in flow_to_image
    max_magnitude = torch.max(magnitude, dim=(1, 2), keepdim=True)[0]
E   TypeError: max() received an invalid combination of arguments - got (Tensor, keepdim=bool, dim=tuple), but expected one of:
E    * (Tensor input, *, Tensor out = None)
E         didn't match because some of the keywords were incorrect: keepdim, dim
E    * (Tensor input, Tensor other, *, Tensor out = None)
E    * (Tensor input, int dim, bool keepdim = False, *, tuple of Tensors out = None)
E    * (Tensor input, name dim, bool keepdim = False, *, tuple of Tensors out = None)
__________________________ test_flow_to_image[False] ___________________________
../publishablew/vision/vision/test/test_utils.py:530: in test_flow_to_image
    img = utils.flow_to_image(flow)
../publishablew/vision/vision/venv/lib/python3.11/site-packages/torch/utils/_contextlib.py:116: in decorate_context
    return func(*args, **kwargs)
../publishablew/vision/vision/torchvision/utils.py:339: in flow_to_image
    return flow_to_image(flow)
../publishablew/vision/vision/torchvision/temp.py:33: in flow_to_image
    max_magnitude = torch.max(magnitude, dim=(1, 2), keepdim=True)[0]
E   TypeError: max() received an invalid combination of arguments - got (Tensor, keepdim=bool, dim=tuple), but expected one of:
E    * (Tensor input, *, Tensor out = None)
E         didn't match because some of the keywords were incorrect: keepdim, dim
E    * (Tensor input, Tensor other, *, Tensor out = None)
E    * (Tensor input, int dim, bool keepdim = False, *, tuple of Tensors out = None)
E    * (Tensor input, name dim, bool keepdim = False, *, tuple of Tensors out = None)
=========================== short test summary info ============================
FAILED ../publishablew/vision/vision/test/test_utils.py::test_flow_to_image[True]
FAILED ../publishablew/vision/vision/test/test_utils.py::test_flow_to_image[False]
============================== 2 failed in 0.24s ===============================


Final Test Result:
============================= test session starts ==============================
platform linux -- Python 3.11.10, pytest-8.3.4, pluggy-1.5.0 -- /local/data0/moved_data/publishablew/vision/vision/venv/bin/python
cachedir: .pytest_cache
rootdir: /local/data0/moved_data/publishablew/vision/vision
configfile: pytest.ini
plugins: mock-3.14.0
collecting ... collected 2 items

../publishablew/vision/vision/test/test_utils.py::test_flow_to_image[True] PASSED
../publishablew/vision/vision/test/test_utils.py::test_flow_to_image[False] PASSED

============================== 2 passed in 0.16s ===============================


Initial Result:
============================= test session starts ==============================
platform linux -- Python 3.11.10, pytest-8.3.4, pluggy-1.5.0 -- /local/data0/moved_data/publishablew/vision/vision/venv/bin/python
cachedir: .pytest_cache
rootdir: /local/data0/moved_data/publishablew/vision/vision
configfile: pytest.ini
plugins: mock-3.14.0
collecting ... collected 2 items

../publishablew/vision/vision/test/test_utils.py::test_flow_to_image[True] PASSED
../publishablew/vision/vision/test/test_utils.py::test_flow_to_image[False] PASSED

============================== 2 passed in 0.16s ===============================
