output file:
processed_pyroblock_diag_embed383.json
function:
block_diag_embed
Error Cases:
ERROR: found no collectors for /local/data0/moved_data/publishablew/pyro/pyro/tests/ops/test_tensor_utils.py::test_block_diag


Pass or Failed: 1

Related Failed Test Cases:
set()

All Test Cases On Generated code:
============================= test session starts ==============================
platform linux -- Python 3.11.10, pytest-8.3.4, pluggy-1.5.0 -- /local/data0/moved_data/publishablew/pyro/pyro/venv/bin/python
cachedir: .pytest_cache
rootdir: /local/data0/moved_data/publishablew/pyro/pyro
configfile: setup.cfg
collecting ... collected 0 items / 1 error

==================================== ERRORS ====================================
_______________ ERROR collecting tests/ops/test_tensor_utils.py ________________
ImportError while importing test module '/local/data0/moved_data/publishablew/pyro/pyro/tests/ops/test_tensor_utils.py'.
Hint: make sure your test modules/packages have valid Python names.
Traceback:
/usr/lib/python3.11/importlib/__init__.py:126: in import_module
    return _bootstrap._gcd_import(name[level:], package, level)
../publishablew/pyro/pyro/tests/ops/test_tensor_utils.py:8: in <module>
    import scipy.fftpack as fftpack
E   ModuleNotFoundError: No module named 'scipy'
=========================== short test summary info ============================
ERROR ../publishablew/pyro/pyro/tests/ops/test_tensor_utils.py
=============================== 1 error in 0.02s ===============================


Final Test Result:
============================= test session starts ==============================
platform linux -- Python 3.11.10, pytest-8.3.4, pluggy-1.5.0 -- /local/data0/moved_data/publishablew/pyro/pyro/venv/bin/python
cachedir: .pytest_cache
rootdir: /local/data0/moved_data/publishablew/pyro/pyro
configfile: setup.cfg
collecting ... collected 0 items / 1 error

==================================== ERRORS ====================================
_______________ ERROR collecting tests/ops/test_tensor_utils.py ________________
ImportError while importing test module '/local/data0/moved_data/publishablew/pyro/pyro/tests/ops/test_tensor_utils.py'.
Hint: make sure your test modules/packages have valid Python names.
Traceback:
/usr/lib/python3.11/importlib/__init__.py:126: in import_module
    return _bootstrap._gcd_import(name[level:], package, level)
../publishablew/pyro/pyro/tests/ops/test_tensor_utils.py:8: in <module>
    import scipy.fftpack as fftpack
E   ModuleNotFoundError: No module named 'scipy'
=========================== short test summary info ============================
ERROR ../publishablew/pyro/pyro/tests/ops/test_tensor_utils.py
=============================== 1 error in 0.02s ===============================


Initial Result:
============================= test session starts ==============================
platform linux -- Python 3.11.10, pytest-8.3.4, pluggy-1.5.0 -- /local/data0/moved_data/publishablew/pyro/pyro/venv/bin/python
cachedir: .pytest_cache
rootdir: /local/data0/moved_data/publishablew/pyro/pyro
configfile: setup.cfg
collecting ... collected 0 items / 1 error

==================================== ERRORS ====================================
_______________ ERROR collecting tests/ops/test_tensor_utils.py ________________
ImportError while importing test module '/local/data0/moved_data/publishablew/pyro/pyro/tests/ops/test_tensor_utils.py'.
Hint: make sure your test modules/packages have valid Python names.
Traceback:
/usr/lib/python3.11/importlib/__init__.py:126: in import_module
    return _bootstrap._gcd_import(name[level:], package, level)
../publishablew/pyro/pyro/tests/ops/test_tensor_utils.py:8: in <module>
    import scipy.fftpack as fftpack
E   ModuleNotFoundError: No module named 'scipy'
=========================== short test summary info ============================
ERROR ../publishablew/pyro/pyro/tests/ops/test_tensor_utils.py
=============================== 1 error in 0.08s ===============================
